Workbook

Sheet Guide
B1: Chamber Resilience Mock-Test Workbook
B2: A practice tool for the incoming Chair: twelve sector tabs with live formulas, a scenario stress-test switch, a dashboard and a scored mock test.
B4: PURPOSE | C4: Practise the Chair's job: read the KPIs of twelve functions, spot the weakest link, and choose the priority action, first in normal conditions and then under shock.
B5: HOW TO USE | C5: 1) Open Control and pick a scenario (Base Case first). 2) Open Dashboard to see the overall score and each sector's red/amber/green status. 3) Open any sector tab to see its inputs, KPIs, weakest KPI and the Chair's action. 4) Take the mock test on Mock_Test.
B6: COLOUR CODE | C6: Blue text on yellow = a value you can edit. Black = a formula (do not overwrite). Green text = a link to another sheet. GREEN / AMBER / RED fills = status.
B7: SCORING | C7: Each KPI scores 100 at its Green threshold and 0 at its Red threshold, in a straight line between. A sector score is the weighted average of its KPI scores. The overall score is the weighted average of the sector scores. Cut-offs (70 and 40) are editable on Control.
B8: SCENARIOS | C8: Control holds six scenarios as multipliers on revenue, input cost, supplier delivery, receivable days, attrition, compliance slippage, payroll errors, downtime and incidents. Edit them to invent your own stress test.
B9: SAMPLE DATA | C9: All base values are illustrative figures for a mid-sized manufacturing chamber (PKR millions where money is shown). Replace them with real data before drawing conclusions. This is a training tool, not an audit or advice.
B10: MOCK TEST | C10: Part A: 24 questions, two per sector, scored automatically; set 'Reveal answers' to Yes to see the key and reasoning. Part B: predict the weakest sector under each scenario and check it against the live dashboard.
B11: TABS | C11: Control | Dashboard | GovAffairs | Policy | PublicAffairs | PublicInterest | HR | OrgInterest | Payroll | Finance | Audit | Commercials | Procurement | Production | Mock_Test

Sheet Control
A1: Control Panel: Scenario, Cut-offs and Weights
A2: Choose a scenario below; every sector tab and the Dashboard recalculate instantly. Blue cells on yellow are editable.
A4: Select active scenario > | B4: Base Case
A6: SCENARIO SHOCK TABLE (edit the multipliers to design your own stress test)
A7: Scenario | B7: Revenue × | C7: Input-cost × | D7: Supplier on-time × | E7: Extra receivable days | F7: Attrition × | G7: Compliance-slip × | H7: Payroll-error × | I7: Downtime × | J7: Incident × | K7: What it simulates
A8: Base Case | B8: 1 | C8: 1 | D8: 1 | E8: 0 | F8: 1 | G8: 1 | H8: 1 | I8: 1 | J8: 1 | K8: Normal operating conditions using the base values you entered.
A9: Supply Shock | B9: 0.95 | C9: 1.18 | D9: 0.82 | E9: 5 | F9: 1 | G9: 1 | H9: 1 | I9: 1.35 | J9: 1.2 | K9: Commodity prices spike and key suppliers deliver late: input costs +18%, supplier on-time delivery -18%, downtime +35%, revenue -5%.
A10: Cash Squeeze | B10: 0.8 | C10: 1.05 | D10: 0.95 | E10: 25 | F10: 1.1 | G10: 1 | H10: 1 | I10: 1 | J10: 1.3 | K10: Customers pay slowly and demand softens: revenue -20%, receivable days +25, attrition +10%.
A11: Regulatory Shock | B11: 0.97 | C11: 1.03 | D11: 1 | E11: 0 | F11: 1 | G11: 3 | H11: 1.5 | I11: 1 | J11: 2 | K11: A new regulation and an enforcement drive: compliance slippage ×3, payroll errors ×1.5, incidents ×2.
A12: Talent Exodus | B12: 0.93 | C12: 1.04 | D12: 0.95 | E12: 0 | F12: 2.2 | G12: 1 | H12: 1.8 | I12: 1.25 | J12: 1.2 | K12: Competitors poach staff and morale falls: attrition ×2.2, payroll errors ×1.8, downtime ×1.25, incidents ×1.2, revenue -7%.
A13: Control Failure / Fraud | B13: 0.98 | C13: 1 | D13: 1 | E13: 3 | F13: 1.2 | G13: 1.5 | H13: 4 | I13: 1 | J13: 3 | K13: Weak payroll and approval controls are exploited: payroll errors ×4, incidents ×3, compliance slippage ×1.5.
A15: ACTIVE FACTORS (live: do not edit)
A16: Currently applied | B16: =INDEX(B$8:B$13,MATCH($B$4,$A$8:$A$13,0)) -> 1 | C16: =INDEX(C$8:C$13,MATCH($B$4,$A$8:$A$13,0)) -> 1 | D16: =INDEX(D$8:D$13,MATCH($B$4,$A$8:$A$13,0)) -> 1 | E16: =INDEX(E$8:E$13,MATCH($B$4,$A$8:$A$13,0)) -> 0 | F16: =INDEX(F$8:F$13,MATCH($B$4,$A$8:$A$13,0)) -> 1 | G16: =INDEX(G$8:G$13,MATCH($B$4,$A$8:$A$13,0)) -> 1 | H16: =INDEX(H$8:H$13,MATCH($B$4,$A$8:$A$13,0)) -> 1 | I16: =INDEX(I$8:I$13,MATCH($B$4,$A$8:$A$13,0)) -> 1 | ... K16: =INDEX(K$8:K$13,MATCH($B$4,$A$8:$A$13,0)) -> Normal operating conditions using the base values you entered.
A18: STATUS CUT-OFFS (score out of 100)
A19: GREEN at or above | B19: 70 | C19: A KPI scores 100 at its Green threshold and 0 at its Red threshold, with a straight line between.
A20: AMBER at or above (below is RED) | B20: 40
A22: SECTOR WEIGHTS FOR THE OVERALL RESILIENCE SCORE
A23: Sector | B23: Weight
A24: Government Affairs | B24: 1
A25: Policy Making | B25: 1
A26: Public Affairs | B26: 1
A27: Public Interest | B27: 1
A28: Human Resources | B28: 1
A29: Organizational Interest | B29: 1
A30: Payroll | B30: 1
A31: Finance | B31: 1
A32: Audit | B32: 1
A33: Commercials | B33: 1
A34: Procurement | B34: 1
A35: Production | B35: 1

Sheet Dashboard
A1: Chamber Resilience Dashboard
A2: Live roll-up of all twelve sectors. Change the scenario on the Control sheet and watch the colours move.
B4: Active scenario | C4: =Control!$B$4 -> Base Case
B5: What it simulates | C5: =Control!$K$16 -> Normal operating conditions using the base values you entered.
B6: Overall resilience score | C6: =SUMPRODUCT(C11:C22,G11:G22)/SUM(G11:G22) -> 77.483277 | D6: =IF(C6>=Control!$B$19,"GREEN",IF(C6>=Control!$B$20,"AMBER","RED")) -> GREEN
B7: Sectors GREEN / AMBER / RED | C7: =COUNTIF($D$11:$D$22,"GREEN") -> 11 | D7: =COUNTIF($D$11:$D$22,"AMBER") -> 1 | E7: =COUNTIF($D$11:$D$22,"RED") -> 0
B8: Weakest sector right now | C8: =INDEX($B$11:$B$22,MATCH(MIN($C$11:$C$22),$C$11:$C$22,0)) -> Policy Making
A10: # | B10: Sector | C10: Score | D10: Status | E10: Weakest KPI | F10: Chair's priority action | G10: Weight | H10: Open tab
A11: 1 | B11: Government Affairs | C11: =GovAffairs!$B$21 -> 76.111111 | D11: =GovAffairs!$B$22 -> GREEN | E11: =GovAffairs!$B$23 -> Institutional contact depth | F11: =GovAffairs!$B$24 -> Name a second senior contact for each regulator; document every channel. | G11: =Control!$B$24 -> 1 | H11: =HYPERLINK("#GovAffairs!A1","Open") -> Open
A12: 2 | B12: Policy Making | C12: =Policy!$B$20 -> 64.351852 | D12: =Policy!$B$21 -> AMBER | E12: =Policy!$B$22 -> Exception rate (exceptions / policies) | F12: =Policy!$B$23 -> Frequent exceptions mean the policy is wrong or ignored. Rewrite it or enforce it. | G12: =Control!$B$25 -> 1 | H12: =HYPERLINK("#Policy!A1","Open") -> Open
A13: 3 | B13: Public Affairs | C13: =PublicAffairs!$B$20 -> 80.666667 | D13: =PublicAffairs!$B$21 -> GREEN | E13: =PublicAffairs!$B$22 -> Holding-statement coverage | F13: =PublicAffairs!$B$23 -> Draft and pre-approve holding statements for every identified crisis scenario. | G13: =Control!$B$26 -> 1 | H13: =HYPERLINK("#PublicAffairs!A1","Open") -> Open
A14: 4 | B14: Public Interest | C14: =PublicInterest!$B$20 -> 70.416667 | D14: =PublicInterest!$B$21 -> GREEN | E14: =PublicInterest!$B$22 -> Public-interest test coverage | F14: =PublicInterest!$B$23 -> Add a mandatory public-interest box to every board paper. | G14: =Control!$B$27 -> 1 | H14: =HYPERLINK("#PublicInterest!A1","Open") -> Open
A15: 5 | B15: Human Resources | C15: =HR!$B$23 -> 83.003553 | D15: =HR!$B$24 -> GREEN | E15: =HR!$B$25 -> Succession coverage | F15: =HR!$B$26 -> Name a successor and an emergency backup for every critical role; start rotation plans. | G15: =Control!$B$28 -> 1 | H15: =HYPERLINK("#HR!A1","Open") -> Open
A16: 6 | B16: Organizational Interest | C16: =OrgInterest!$B$24 -> 72.399591 | D16: =OrgInterest!$B$25 -> GREEN | E16: =OrgInterest!$B$26 -> Related-party transactions reviewed | F16: =OrgInterest!$B$27 -> Route every related-party transaction through the committee; no retrospective approvals. | G16: =Control!$B$29 -> 1 | H16: =HYPERLINK("#OrgInterest!A1","Open") -> Open
A17: 7 | B17: Payroll | C17: =Payroll!$B$23 -> 77.587302 | D17: =Payroll!$B$24 -> GREEN | E17: =Payroll!$B$25 -> Overrides without prior approval | F17: =Payroll!$B$26 -> Block post-run approvals: no override without sign-off before the run. | G17: =Control!$B$30 -> 1 | H17: =HYPERLINK("#Payroll!A1","Open") -> Open
A18: 8 | B18: Finance | C18: =Finance!$B$23 -> 93.019608 | D18: =Finance!$B$24 -> GREEN | E18: =Finance!$B$25 -> Days sales outstanding | F18: =Finance!$B$26 -> Sector healthy. Keep the quarterly review and watch: Days sales outstanding | G18: =Control!$B$31 -> 1 | H18: =HYPERLINK("#Finance!A1","Open") -> Open
A19: 9 | B19: Audit | C19: =Audit!$B$23 -> 72.857143 | D19: =Audit!$B$24 -> GREEN | E19: =Audit!$B$25 -> Overdue share of open findings | F19: =Audit!$B$26 -> Escalate every overdue finding to the Audit & Risk committee with the owner present. | G19: =Control!$B$32 -> 1 | H19: =HYPERLINK("#Audit!A1","Open") -> Open
A20: 10 | B20: Commercials | C20: =Commercials!$B$24 -> 82.752381 | D20: =Commercials!$B$25 -> GREEN | E20: =Commercials!$B$26 -> Contract renewal rate | F20: =Commercials!$B$27 -> Start renewal conversations 120 days out; review churn reasons. | G20: =Control!$B$33 -> 1 | H20: =HYPERLINK("#Commercials!A1","Open") -> Open
A21: 11 | B21: Procurement | C21: =Procurement!$B$28 -> 74.623016 | D21: =Procurement!$B$29 -> GREEN | E21: =Procurement!$B$30 -> Plan-B coverage of critical categories | F21: =Procurement!$B$31 -> Write and test a plan B for every critical category without one. | G21: =Control!$B$34 -> 1 | H21: =HYPERLINK("#Procurement!A1","Open") -> Open
A22: 12 | B22: Production | C22: =Production!$B$23 -> 82.010441 | D22: =Production!$B$24 -> GREEN | E22: =Production!$B$25 -> Lost-time injuries | F22: =Production!$B$26 -> Treat every injury as a board-level event; independent safety review within 30 days. | G22: =Control!$B$35 -> 1 | H22: =HYPERLINK("#Production!A1","Open") -> Open

Sheet GovAffairs
A1: 1. Government Affairs
A2: Stance: relationships with regulators belong to the institution, not to the person who holds them. Move them from personal rapport to documented channels.
A3: Active scenario: | B3: =Control!$B$4 -> Base Case
A5: A. INPUTS (blue on yellow = edit the base value; the scenario-adjusted column recalculates from the Control sheet)
A6: Input | B6: Unit | C6: Base value | D6: Scenario-adjusted | E6: Note
A7: Regulatory filings due this year | B7: count | C7: 48 | D7: =C7 -> 48 | E7: From the compliance calendar
A8: Filings submitted late | B8: count | C8: 1 | D8: =C8*Control!$G$16 -> 1 | E8: Includes extensions not pre-approved
A9: Regulators / ministries mapped | B9: count | C9: 12 | D9: =C9 -> 12 | E9: From the regulator map
A10: Regulators with 2+ named institutional contacts | B10: count | C10: 9 | D10: =C10 -> 9 | E10: Institutional, not personal, relationships
A11: Open regulatory queries | B11: count | C11: 6 | D11: =C11*Control!$G$16 -> 6
A12: Average age of open queries | B12: days | C12: 22 | D12: =C12*(1+(Control!$G$16-1)*0.5) -> 22
A14: B. KPI DASHBOARD
A15: KPI | B15: Value | C15: Green at | D15: Red at | E15: Direction | F15: Score (0-100) | G15: Status | H15: Weight | I15: Chair's action if this is the weakest KPI
A16: On-time filing rate | B16: =IFERROR(($D$7-$D$8)/$D$7,0) -> 0.97916667 | C16: 0.99 | D16: 0.9 | E16: Higher is better | F16: =IF(C16=D16,IF(B16>=C16,100,0),MAX(0,MIN(100,(B16-D16)/(C16-D16)*100))) -> 87.962963 | G16: =IF(F16>=Control!$B$19,"GREEN",IF(F16>=Control!$B$20,"AMBER","RED")) -> GREEN | H16: 3 | I16: Rebuild the compliance calendar under Audit ownership and clear the root cause of every late filing.
A17: Average age of open queries (days) | B17: =IFERROR($D$12,0) -> 22 | C17: 15 | D17: 45 | E17: Lower is better | F17: =IF(C17=D17,IF(B17>=C17,100,0),MAX(0,MIN(100,(B17-D17)/(C17-D17)*100))) -> 76.666667 | G17: =IF(F17>=Control!$B$19,"GREEN",IF(F17>=Control!$B$20,"AMBER","RED")) -> GREEN | H17: 2 | I17: Give every open regulatory query a named owner and a response deadline.
A18: Open regulatory queries | B18: =IFERROR($D$11,0) -> 6 | C18: 3 | D18: 12 | E18: Lower is better | F18: =IF(C18=D18,IF(B18>=C18,100,0),MAX(0,MIN(100,(B18-D18)/(C18-D18)*100))) -> 66.666667 | G18: =IF(F18>=Control!$B$19,"GREEN",IF(F18>=Control!$B$20,"AMBER","RED")) -> AMBER | H18: 1 | I18: Hold a weekly query-clearing session until the backlog is under control.
A19: Institutional contact depth | B19: =IFERROR($D$10/$D$9,0) -> 0.75 | C19: 0.9 | D19: 0.5 | E19: Higher is better | F19: =IF(C19=D19,IF(B19>=C19,100,0),MAX(0,MIN(100,(B19-D19)/(C19-D19)*100))) -> 62.5 | G19: =IF(F19>=Control!$B$19,"GREEN",IF(F19>=Control!$B$20,"AMBER","RED")) -> AMBER | H19: 2 | I19: Name a second senior contact for each regulator; document every channel.
A21: SECTOR SCORE (0-100, weighted) | B21: =SUMPRODUCT($F$16:$F$19,$H$16:$H$19)/SUM($H$16:$H$19) -> 76.111111
A22: SECTOR STATUS | B22: =IF(B21>=Control!$B$19,"GREEN",IF(B21>=Control!$B$20,"AMBER","RED")) -> GREEN
A23: WEAKEST KPI | B23: =INDEX($A$16:$A$19,MATCH(MIN($F$16:$F$19),$F$16:$F$19,0)) -> Institutional contact depth
A24: CHAIR'S PRIORITY ACTION | B24: =IF(MIN($F$16:$F$19)>=Control!$B$19,"Sector healthy. Keep the quarterly review and watch: "&B23,INDEX($I$16:$I$19,MATCH(MIN($F$16:$F$19),$F$16:$F$19,0))) -> Name a second senior contact for each regulator; document every channel.

Sheet Policy
A1: 2. Policy Making
A2: Stance: internal policy is the chamber's operating law. If it is not written, owned and in date, it does not exist.
A3: Active scenario: | B3: =Control!$B$4 -> Base Case
A5: A. INPUTS (blue on yellow = edit the base value; the scenario-adjusted column recalculates from the Control sheet)
A6: Input | B6: Unit | C6: Base value | D6: Scenario-adjusted | E6: Note
A7: Policies in the register | B7: count | C7: 60 | D7: =C7 -> 60 | E7: Policy register
A8: Policies within their review date | B8: count | C8: 54 | D8: =C8 -> 54
A9: Exceptions granted this quarter | B9: count | C9: 9 | D9: =C9*Control!$G$16 -> 9
A10: Policies with a named owner | B10: count | C10: 57 | D10: =C10 -> 57
A11: Policy breaches reported this year | B11: count | C11: 4 | D11: =C11*Control!$G$16 -> 4
A13: B. KPI DASHBOARD
A14: KPI | B14: Value | C14: Green at | D14: Red at | E14: Direction | F14: Score (0-100) | G14: Status | H14: Weight | I14: Chair's action if this is the weakest KPI
A15: Policies in date | B15: =IFERROR($D$8/$D$7,0) -> 0.9 | C15: 0.95 | D15: 0.75 | E15: Higher is better | F15: =IF(C15=D15,IF(B15>=C15,100,0),MAX(0,MIN(100,(B15-D15)/(C15-D15)*100))) -> 75 | G15: =IF(F15>=Control!$B$19,"GREEN",IF(F15>=Control!$B$20,"AMBER","RED")) -> GREEN | H15: 2 | I15: Fix a review calendar: annual for high-risk policies, every three years for the rest.
A16: Exception rate (exceptions / policies) | B16: =IFERROR($D$9/$D$7,0) -> 0.15 | C16: 0.05 | D16: 0.25 | E16: Lower is better | F16: =IF(C16=D16,IF(B16>=C16,100,0),MAX(0,MIN(100,(B16-D16)/(C16-D16)*100))) -> 50 | G16: =IF(F16>=Control!$B$19,"GREEN",IF(F16>=Control!$B$20,"AMBER","RED")) -> AMBER | H16: 2 | I16: Frequent exceptions mean the policy is wrong or ignored. Rewrite it or enforce it.
A17: Ownership coverage | B17: =IFERROR($D$10/$D$7,0) -> 0.95 | C17: 1 | D17: 0.85 | E17: Higher is better | F17: =IF(C17=D17,IF(B17>=C17,100,0),MAX(0,MIN(100,(B17-D17)/(C17-D17)*100))) -> 66.666667 | G17: =IF(F17>=Control!$B$19,"GREEN",IF(F17>=Control!$B$20,"AMBER","RED")) -> AMBER | H17: 1 | I17: Assign an accountable owner to every policy without one.
A18: Breaches per 100 policies | B18: =IFERROR($D$11/$D$7*100,0) -> 6.6666667 | C18: 3 | D18: 15 | E18: Lower is better | F18: =IF(C18=D18,IF(B18>=C18,100,0),MAX(0,MIN(100,(B18-D18)/(C18-D18)*100))) -> 69.444444 | G18: =IF(F18>=Control!$B$19,"GREEN",IF(F18>=Control!$B$20,"AMBER","RED")) -> AMBER | H18: 1 | I18: Root-cause each breach and report themes to the Audit & Risk committee.
A20: SECTOR SCORE (0-100, weighted) | B20: =SUMPRODUCT($F$15:$F$18,$H$15:$H$18)/SUM($H$15:$H$18) -> 64.351852
A21: SECTOR STATUS | B21: =IF(B20>=Control!$B$19,"GREEN",IF(B20>=Control!$B$20,"AMBER","RED")) -> AMBER
A22: WEAKEST KPI | B22: =INDEX($A$15:$A$18,MATCH(MIN($F$15:$F$18),$F$15:$F$18,0)) -> Exception rate (exceptions / policies)
A23: CHAIR'S PRIORITY ACTION | B23: =IF(MIN($F$15:$F$18)>=Control!$B$19,"Sector healthy. Keep the quarterly review and watch: "&B22,INDEX($I$15:$I$18,MATCH(MIN($F$15:$F$18),$F$15:$F$18,0))) -> Frequent exceptions mean the policy is wrong or ignored. Rewrite it or enforce it.

Sheet PublicAffairs
A1: 3. Public Affairs
A2: Stance: one voice, one set of facts. Reputation is built slowly and lost in a single bad news cycle.
A3: Active scenario: | B3: =Control!$B$4 -> Base Case
A5: A. INPUTS (blue on yellow = edit the base value; the scenario-adjusted column recalculates from the Control sheet)
A6: Input | B6: Unit | C6: Base value | D6: Scenario-adjusted | E6: Note
A7: Average response time to a stakeholder or media issue | B7: hours | C7: 6 | D7: =C7*(1+(Control!$J$16-1)*0.5) -> 6
A8: Stakeholder trust survey score | B8: % | C8: 0.78 | D8: =C8*(1-(Control!$J$16-1)*0.05) -> 0.78 | E8: Annual survey
A9: Crisis scenarios identified | B9: count | C9: 5 | D9: =C9 -> 5 | E9: Supply disruption, data breach, leadership vacancy, regulatory action, etc.
A10: Scenarios with an approved holding statement | B10: count | C10: 4 | D10: =C10 -> 4
A11: Reputation incidents this year | B11: count | C11: 3 | D11: =C11*Control!$J$16 -> 3
A13: B. KPI DASHBOARD
A14: KPI | B14: Value | C14: Green at | D14: Red at | E14: Direction | F14: Score (0-100) | G14: Status | H14: Weight | I14: Chair's action if this is the weakest KPI
A15: Response time to issues (hours) | B15: =IFERROR($D$7,0) -> 6 | C15: 4 | D15: 24 | E15: Lower is better | F15: =IF(C15=D15,IF(B15>=C15,100,0),MAX(0,MIN(100,(B15-D15)/(C15-D15)*100))) -> 90 | G15: =IF(F15>=Control!$B$19,"GREEN",IF(F15>=Control!$B$20,"AMBER","RED")) -> GREEN | H15: 2 | I15: Publish an authorized spokesperson list and a 4-hour first-response rule.
A16: Stakeholder trust score | B16: =IFERROR($D$8,0) -> 0.78 | C16: 0.8 | D16: 0.55 | E16: Higher is better | F16: =IF(C16=D16,IF(B16>=C16,100,0),MAX(0,MIN(100,(B16-D16)/(C16-D16)*100))) -> 92 | G16: =IF(F16>=Control!$B$19,"GREEN",IF(F16>=Control!$B$20,"AMBER","RED")) -> GREEN | H16: 2 | I16: Commission a listening exercise and publish a short plain-language accountability report.
A17: Holding-statement coverage | B17: =IFERROR($D$10/$D$9,0) -> 0.8 | C17: 1 | D17: 0.5 | E17: Higher is better | F17: =IF(C17=D17,IF(B17>=C17,100,0),MAX(0,MIN(100,(B17-D17)/(C17-D17)*100))) -> 60 | G17: =IF(F17>=Control!$B$19,"GREEN",IF(F17>=Control!$B$20,"AMBER","RED")) -> AMBER | H17: 1 | I17: Draft and pre-approve holding statements for every identified crisis scenario.
A18: Reputation incidents | B18: =IFERROR($D$11,0) -> 3 | C18: 1 | D18: 6 | E18: Lower is better | F18: =IF(C18=D18,IF(B18>=C18,100,0),MAX(0,MIN(100,(B18-D18)/(C18-D18)*100))) -> 60 | G18: =IF(F18>=Control!$B$19,"GREEN",IF(F18>=Control!$B$20,"AMBER","RED")) -> AMBER | H18: 1 | I18: Run a post-incident review for each event and feed the lessons into the crisis protocol.
A20: SECTOR SCORE (0-100, weighted) | B20: =SUMPRODUCT($F$15:$F$18,$H$15:$H$18)/SUM($H$15:$H$18) -> 80.666667
A21: SECTOR STATUS | B21: =IF(B20>=Control!$B$19,"GREEN",IF(B20>=Control!$B$20,"AMBER","RED")) -> GREEN
A22: WEAKEST KPI | B22: =INDEX($A$15:$A$18,MATCH(MIN($F$15:$F$18),$F$15:$F$18,0)) -> Holding-statement coverage
A23: CHAIR'S PRIORITY ACTION | B23: =IF(MIN($F$15:$F$18)>=Control!$B$19,"Sector healthy. Keep the quarterly review and watch: "&B22,INDEX($I$15:$I$18,MATCH(MIN($F$15:$F$18),$F$15:$F$18,0))) -> Draft and pre-approve holding statements for every identified crisis scenario.

Sheet PublicInterest
A1: 4. Public Interest
A2: Stance: legitimacy comes from serving more than our members. Where member and public interest conflict, disclose and decide openly.
A3: Active scenario: | B3: =Control!$B$4 -> Base Case
A5: A. INPUTS (blue on yellow = edit the base value; the scenario-adjusted column recalculates from the Control sheet)
A6: Input | B6: Unit | C6: Base value | D6: Scenario-adjusted | E6: Note
A7: Major board decisions this year | B7: count | C7: 24 | D7: =C7 -> 24
A8: Decisions with a documented public-interest test | B8: count | C8: 20 | D8: =C8 -> 20
A9: Whistleblower cases received | B9: count | C9: 5 | D9: =C9*Control!$J$16 -> 5
A10: Cases closed within 60 days | B10: count | C10: 4 | D10: =C10 -> 4
A11: Impact-report sections completed | B11: count | C11: 7 | D11: =C11 -> 7 | E11: Community, environment, employment, etc.
A12: Impact-report sections required | B12: count | C12: 8 | D12: =C12 -> 8
A14: B. KPI DASHBOARD
A15: KPI | B15: Value | C15: Green at | D15: Red at | E15: Direction | F15: Score (0-100) | G15: Status | H15: Weight | I15: Chair's action if this is the weakest KPI
A16: Public-interest test coverage | B16: =IFERROR($D$8/$D$7,0) -> 0.83333333 | C16: 0.95 | D16: 0.6 | E16: Higher is better | F16: =IF(C16=D16,IF(B16>=C16,100,0),MAX(0,MIN(100,(B16-D16)/(C16-D16)*100))) -> 66.666667 | G16: =IF(F16>=Control!$B$19,"GREEN",IF(F16>=Control!$B$20,"AMBER","RED")) -> AMBER | H16: 2 | I16: Add a mandatory public-interest box to every board paper.
A17: Whistleblower closure rate (60 days) | B17: =IFERROR(IF($D$9=0,1,MIN(1,$D$10/$D$9)),0) -> 0.8 | C17: 0.9 | D17: 0.5 | E17: Higher is better | F17: =IF(C17=D17,IF(B17>=C17,100,0),MAX(0,MIN(100,(B17-D17)/(C17-D17)*100))) -> 75 | G17: =IF(F17>=Control!$B$19,"GREEN",IF(F17>=Control!$B$20,"AMBER","RED")) -> GREEN | H17: 2 | I17: Resource the Audit & Risk committee to close cases fast; report the ageing monthly.
A18: Impact reporting completeness | B18: =IFERROR($D$11/$D$12,0) -> 0.875 | C18: 1 | D18: 0.6 | E18: Higher is better | F18: =IF(C18=D18,IF(B18>=C18,100,0),MAX(0,MIN(100,(B18-D18)/(C18-D18)*100))) -> 68.75 | G18: =IF(F18>=Control!$B$19,"GREEN",IF(F18>=Control!$B$20,"AMBER","RED")) -> AMBER | H18: 1 | I18: Assign an owner and a data source to every missing impact-report section.
A20: SECTOR SCORE (0-100, weighted) | B20: =SUMPRODUCT($F$16:$F$18,$H$16:$H$18)/SUM($H$16:$H$18) -> 70.416667
A21: SECTOR STATUS | B21: =IF(B20>=Control!$B$19,"GREEN",IF(B20>=Control!$B$20,"AMBER","RED")) -> GREEN
A22: WEAKEST KPI | B22: =INDEX($A$16:$A$18,MATCH(MIN($F$16:$F$18),$F$16:$F$18,0)) -> Public-interest test coverage
A23: CHAIR'S PRIORITY ACTION | B23: =IF(MIN($F$16:$F$18)>=Control!$B$19,"Sector healthy. Keep the quarterly review and watch: "&B22,INDEX($I$16:$I$18,MATCH(MIN($F$16:$F$18),$F$16:$F$18,0))) -> Add a mandatory public-interest box to every board paper.

Sheet HR
A1: 5. Human Resources
A2: Stance: succession depth is the real measure of a tenure. If the organization needs one person, it is fragile.
A3: Active scenario: | B3: =Control!$B$4 -> Base Case
A5: A. INPUTS (blue on yellow = edit the base value; the scenario-adjusted column recalculates from the Control sheet)
A6: Input | B6: Unit | C6: Base value | D6: Scenario-adjusted | E6: Note
A7: Headcount | B7: people | C7: 420 | D7: =C7 -> 420
A8: Critical roles | B8: count | C8: 30 | D8: =C8 -> 30
A9: Critical roles with a ready-now successor | B9: count | C9: 22 | D9: =C9 -> 22
A10: Leavers (annualized) | B10: people | C10: 34 | D10: =C10*Control!$F$16 -> 34
A11: Regretted leavers (annualized) | B11: people | C11: 8 | D11: =C11*Control!$F$16 -> 8 | E11: Leavers the institution wanted to keep
A12: Average time to fill a vacancy | B12: days | C12: 48 | D12: =C12*(1+(Control!$F$16-1)*0.5) -> 48
A13: Engagement survey score | B13: % | C13: 0.74 | D13: =C13*(1-(Control!$F$16-1)*0.05) -> 0.74
A15: B. KPI DASHBOARD
A16: KPI | B16: Value | C16: Green at | D16: Red at | E16: Direction | F16: Score (0-100) | G16: Status | H16: Weight | I16: Chair's action if this is the weakest KPI
A17: Succession coverage | B17: =IFERROR($D$9/$D$8,0) -> 0.73333333 | C17: 0.85 | D17: 0.5 | E17: Higher is better | F17: =IF(C17=D17,IF(B17>=C17,100,0),MAX(0,MIN(100,(B17-D17)/(C17-D17)*100))) -> 66.666667 | G17: =IF(F17>=Control!$B$19,"GREEN",IF(F17>=Control!$B$20,"AMBER","RED")) -> AMBER | H17: 3 | I17: Name a successor and an emergency backup for every critical role; start rotation plans.
A18: Attrition rate | B18: =IFERROR($D$10/$D$7,0) -> 0.080952381 | C18: 0.08 | D18: 0.2 | E18: Lower is better | F18: =IF(C18=D18,IF(B18>=C18,100,0),MAX(0,MIN(100,(B18-D18)/(C18-D18)*100))) -> 99.206349 | G18: =IF(F18>=Control!$B$19,"GREEN",IF(F18>=Control!$B$20,"AMBER","RED")) -> GREEN | H18: 2 | I18: Run stay interviews and fix the top three drivers before offering pay rises.
A19: Regretted attrition rate | B19: =IFERROR($D$11/$D$7,0) -> 0.019047619 | C19: 0.015 | D19: 0.06 | E19: Lower is better | F19: =IF(C19=D19,IF(B19>=C19,100,0),MAX(0,MIN(100,(B19-D19)/(C19-D19)*100))) -> 91.005291 | G19: =IF(F19>=Control!$B$19,"GREEN",IF(F19>=Control!$B$20,"AMBER","RED")) -> GREEN | H19: 2 | I19: Review compensation, workload and career paths for the roles being lost.
A20: Time to fill (days) | B20: =IFERROR($D$12,0) -> 48 | C20: 40 | D20: 90 | E20: Lower is better | F20: =IF(C20=D20,IF(B20>=C20,100,0),MAX(0,MIN(100,(B20-D20)/(C20-D20)*100))) -> 84 | G20: =IF(F20>=Control!$B$19,"GREEN",IF(F20>=Control!$B$20,"AMBER","RED")) -> GREEN | H20: 1 | I20: Pre-build talent pools for critical roles and shorten approval chains.
A21: Engagement score | B21: =IFERROR($D$13,0) -> 0.74 | C21: 0.78 | D21: 0.55 | E21: Higher is better | F21: =IF(C21=D21,IF(B21>=C21,100,0),MAX(0,MIN(100,(B21-D21)/(C21-D21)*100))) -> 82.608696 | G21: =IF(F21>=Control!$B$19,"GREEN",IF(F21>=Control!$B$20,"AMBER","RED")) -> GREEN | H21: 1 | I21: Publish survey results and commit to two visible actions this quarter.
A23: SECTOR SCORE (0-100, weighted) | B23: =SUMPRODUCT($F$17:$F$21,$H$17:$H$21)/SUM($H$17:$H$21) -> 83.003553
A24: SECTOR STATUS | B24: =IF(B23>=Control!$B$19,"GREEN",IF(B23>=Control!$B$20,"AMBER","RED")) -> GREEN
A25: WEAKEST KPI | B25: =INDEX($A$17:$A$21,MATCH(MIN($F$17:$F$21),$F$17:$F$21,0)) -> Succession coverage
A26: CHAIR'S PRIORITY ACTION | B26: =IF(MIN($F$17:$F$21)>=Control!$B$19,"Sector healthy. Keep the quarterly review and watch: "&B25,INDEX($I$17:$I$21,MATCH(MIN($F$17:$F$21),$F$17:$F$21,0))) -> Name a successor and an emergency backup for every critical role; start rotation plans.

Sheet OrgInterest
A1: 6. Organizational Interest
A2: Stance: the institution's long-term health outranks any individual, faction or term of office.
A3: Active scenario: | B3: =Control!$B$4 -> Base Case
A5: A. INPUTS (blue on yellow = edit the base value; the scenario-adjusted column recalculates from the Control sheet)
A6: Input | B6: Unit | C6: Base value | D6: Scenario-adjusted | E6: Note
A7: Board members | B7: people | C7: 11 | D7: =C7 -> 11
A8: Annual conflict-of-interest declarations received | B8: count | C8: 11 | D8: =C8 -> 11
A9: Related-party transactions this year | B9: count | C9: 14 | D9: =C9 -> 14
A10: Related-party transactions not reviewed by committee | B10: count | C10: 1 | D10: =C10*Control!$J$16 -> 1
A11: Directors beyond their term limit | B11: people | C11: 1 | D11: =C11 -> 1
A12: Board attendance rate | B12: % | C12: 0.91 | D12: =C12*(1-(Control!$J$16-1)*0.04) -> 0.91
A13: Governance documents (bylaws, charters, matrices) | B13: count | C13: 9 | D13: =C13 -> 9
A14: Governance documents within their review cycle | B14: count | C14: 8 | D14: =C14 -> 8
A16: B. KPI DASHBOARD
A17: KPI | B17: Value | C17: Green at | D17: Red at | E17: Direction | F17: Score (0-100) | G17: Status | H17: Weight | I17: Chair's action if this is the weakest KPI
A18: Conflict-of-interest declaration completeness | B18: =IFERROR($D$8/$D$7,0) -> 1 | C18: 1 | D18: 0.8 | E18: Higher is better | F18: =IF(C18=D18,IF(B18>=C18,100,0),MAX(0,MIN(100,(B18-D18)/(C18-D18)*100))) -> 100 | G18: =IF(F18>=Control!$B$19,"GREEN",IF(F18>=Control!$B$20,"AMBER","RED")) -> GREEN | H18: 2 | I18: Collect every missing declaration before the next meeting; refresh at each meeting.
A19: Related-party transactions reviewed | B19: =IFERROR(1-$D$10/$D$9,0) -> 0.92857143 | C19: 1 | D19: 0.85 | E19: Higher is better | F19: =IF(C19=D19,IF(B19>=C19,100,0),MAX(0,MIN(100,(B19-D19)/(C19-D19)*100))) -> 52.380952 | G19: =IF(F19>=Control!$B$19,"GREEN",IF(F19>=Control!$B$20,"AMBER","RED")) -> AMBER | H19: 3 | I19: Route every related-party transaction through the committee; no retrospective approvals.
A20: Directors beyond term limit | B20: =IFERROR($D$11/$D$7,0) -> 0.090909091 | C20: 0 | D20: 0.25 | E20: Lower is better | F20: =IF(C20=D20,IF(B20>=C20,100,0),MAX(0,MIN(100,(B20-D20)/(C20-D20)*100))) -> 63.636364 | G20: =IF(F20>=Control!$B$19,"GREEN",IF(F20>=Control!$B$20,"AMBER","RED")) -> AMBER | H20: 1 | I20: Enforce term limits and staggered rotation; plan renewals in advance.
A21: Board attendance | B21: =IFERROR($D$12,0) -> 0.91 | C21: 0.92 | D21: 0.7 | E21: Higher is better | F21: =IF(C21=D21,IF(B21>=C21,100,0),MAX(0,MIN(100,(B21-D21)/(C21-D21)*100))) -> 95.454545 | G21: =IF(F21>=Control!$B$19,"GREEN",IF(F21>=Control!$B$20,"AMBER","RED")) -> GREEN | H21: 1 | I21: Fix the calendar a year ahead; follow up persistent absence through the nominations committee.
A22: Governance documents in review cycle | B22: =IFERROR($D$14/$D$13,0) -> 0.88888889 | C22: 1 | D22: 0.7 | E22: Higher is better | F22: =IF(C22=D22,IF(B22>=C22,100,0),MAX(0,MIN(100,(B22-D22)/(C22-D22)*100))) -> 62.962963 | G22: =IF(F22>=Control!$B$19,"GREEN",IF(F22>=Control!$B$20,"AMBER","RED")) -> AMBER | H22: 1 | I22: Schedule the overdue document reviews and assign owners.
A24: SECTOR SCORE (0-100, weighted) | B24: =SUMPRODUCT($F$18:$F$22,$H$18:$H$22)/SUM($H$18:$H$22) -> 72.399591
A25: SECTOR STATUS | B25: =IF(B24>=Control!$B$19,"GREEN",IF(B24>=Control!$B$20,"AMBER","RED")) -> GREEN
A26: WEAKEST KPI | B26: =INDEX($A$18:$A$22,MATCH(MIN($F$18:$F$22),$F$18:$F$22,0)) -> Related-party transactions reviewed
A27: CHAIR'S PRIORITY ACTION | B27: =IF(MIN($F$18:$F$22)>=Control!$B$19,"Sector healthy. Keep the quarterly review and watch: "&B26,INDEX($I$18:$I$22,MATCH(MIN($F$18:$F$22),$F$18:$F$22,0))) -> Route every related-party transaction through the committee; no retrospective approvals.

Sheet Payroll
A1: 7. Payroll
A2: Stance: payroll is where trust with employees is tested every month. Errors here do more cultural damage than most strategic mistakes.
A3: Active scenario: | B3: =Control!$B$4 -> Base Case
A5: A. INPUTS (blue on yellow = edit the base value; the scenario-adjusted column recalculates from the Control sheet)
A6: Input | B6: Unit | C6: Base value | D6: Scenario-adjusted | E6: Note
A7: Employees paid per run | B7: people | C7: 420 | D7: =C7 -> 420
A8: Payroll runs per year | B8: count | C8: 12 | D8: =C8 -> 12
A9: Payslips with errors (per year) | B9: count | C9: 4 | D9: =C9*Control!$H$16 -> 4
A10: Off-cycle payments (per year) | B10: count | C10: 12 | D10: =C10*Control!$H$16 -> 12
A11: Overrides without prior approval (per year) | B11: count | C11: 2 | D11: =C11*Control!$H$16 -> 2
A12: Payroll-to-ledger variance (share of payroll) | B12: % | C12: 0.002 | D12: =C12*Control!$H$16 -> 0.002
A13: Master-data flags (ghost or duplicate bank accounts) | B13: count | C13: 1 | D13: =C13*Control!$H$16 -> 1 | E13: From the periodic master-data audit
A15: B. KPI DASHBOARD
A16: KPI | B16: Value | C16: Green at | D16: Red at | E16: Direction | F16: Score (0-100) | G16: Status | H16: Weight | I16: Chair's action if this is the weakest KPI
A17: Payslip error rate | B17: =IFERROR($D$9/$D$7,0) -> 0.0095238095 | C17: 0.005 | D17: 0.03 | E17: Lower is better | F17: =IF(C17=D17,IF(B17>=C17,100,0),MAX(0,MIN(100,(B17-D17)/(C17-D17)*100))) -> 81.904762 | G17: =IF(F17>=Control!$B$19,"GREEN",IF(F17>=Control!$B$20,"AMBER","RED")) -> GREEN | H17: 3 | I17: Add a pre-run exception report and a second-person check on all pay changes.
A18: Off-cycle payments per run | B18: =IFERROR($D$10/$D$8,0) -> 1 | C18: 0.5 | D18: 4 | E18: Lower is better | F18: =IF(C18=D18,IF(B18>=C18,100,0),MAX(0,MIN(100,(B18-D18)/(C18-D18)*100))) -> 85.714286 | G18: =IF(F18>=Control!$B$19,"GREEN",IF(F18>=Control!$B$20,"AMBER","RED")) -> GREEN | H18: 1 | I18: Investigate each off-cycle payment; fix the upstream cut-off or data-entry cause.
A19: Overrides without prior approval | B19: =IFERROR($D$11,0) -> 2 | C19: 0 | D19: 6 | E19: Lower is better | F19: =IF(C19=D19,IF(B19>=C19,100,0),MAX(0,MIN(100,(B19-D19)/(C19-D19)*100))) -> 66.666667 | G19: =IF(F19>=Control!$B$19,"GREEN",IF(F19>=Control!$B$20,"AMBER","RED")) -> AMBER | H19: 2 | I19: Block post-run approvals: no override without sign-off before the run.
A20: Ledger reconciliation variance | B20: =IFERROR($D$12,0) -> 0.002 | C20: 0.001 | D20: 0.01 | E20: Lower is better | F20: =IF(C20=D20,IF(B20>=C20,100,0),MAX(0,MIN(100,(B20-D20)/(C20-D20)*100))) -> 88.888889 | G20: =IF(F20>=Control!$B$19,"GREEN",IF(F20>=Control!$B$20,"AMBER","RED")) -> GREEN | H20: 2 | I20: Reconcile payroll to the general ledger and headcount every month; investigate every variance.
A21: Master-data flags | B21: =IFERROR($D$13,0) -> 1 | C21: 0 | D21: 3 | E21: Lower is better | F21: =IF(C21=D21,IF(B21>=C21,100,0),MAX(0,MIN(100,(B21-D21)/(C21-D21)*100))) -> 66.666667 | G21: =IF(F21>=Control!$B$19,"GREEN",IF(F21>=Control!$B$20,"AMBER","RED")) -> AMBER | H21: 2 | I21: Audit the employee master file for ghost and duplicate accounts; separate data-change and approval duties.
A23: SECTOR SCORE (0-100, weighted) | B23: =SUMPRODUCT($F$17:$F$21,$H$17:$H$21)/SUM($H$17:$H$21) -> 77.587302
A24: SECTOR STATUS | B24: =IF(B23>=Control!$B$19,"GREEN",IF(B23>=Control!$B$20,"AMBER","RED")) -> GREEN
A25: WEAKEST KPI | B25: =INDEX($A$17:$A$21,MATCH(MIN($F$17:$F$21),$F$17:$F$21,0)) -> Overrides without prior approval
A26: CHAIR'S PRIORITY ACTION | B26: =IF(MIN($F$17:$F$21)>=Control!$B$19,"Sector healthy. Keep the quarterly review and watch: "&B25,INDEX($I$17:$I$21,MATCH(MIN($F$17:$F$21),$F$17:$F$21,0))) -> Block post-run approvals: no override without sign-off before the run.

Sheet Finance
A1: 8. Finance
A2: Stance: resilience means surviving the bad year, so build for it. Reserves, diversification and stress tests are the discipline.
A3: Active scenario: | B3: =Control!$B$4 -> Base Case
A5: A. INPUTS (blue on yellow = edit the base value; the scenario-adjusted column recalculates from the Control sheet)
A6: Input | B6: Unit | C6: Base value | D6: Scenario-adjusted | E6: Note
A7: Annual revenue | B7: PKR m | C7: 12000 | D7: =C7*Control!$B$16 -> 12000 | E7: Illustrative figures; replace with your own
A8: Budgeted revenue | B8: PKR m | C8: 12000 | D8: =C8 -> 12000
A9: Raw-material and input costs | B9: PKR m | C9: 6400 | D9: =C9*Control!$C$16 -> 6400
A10: Other operating costs | B10: PKR m | C10: 3800 | D10: =C10 -> 3800
A11: Liquid reserves | B11: PKR m | C11: 4800 | D11: =C11 -> 4800
A12: Largest single income source | B12: PKR m | C12: 2640 | D12: =C12 -> 2640
A13: Days sales outstanding | B13: days | C13: 52 | D13: =C13+Control!$E$16 -> 52
A15: B. KPI DASHBOARD
A16: KPI | B16: Value | C16: Green at | D16: Red at | E16: Direction | F16: Score (0-100) | G16: Status | H16: Weight | I16: Chair's action if this is the weakest KPI
A17: Operating margin | B17: =IFERROR(($D$7-$D$9-$D$10)/$D$7,0) -> 0.15 | C17: 0.15 | D17: 0.03 | E17: Higher is better | F17: =IF(C17=D17,IF(B17>=C17,100,0),MAX(0,MIN(100,(B17-D17)/(C17-D17)*100))) -> 100 | G17: =IF(F17>=Control!$B$19,"GREEN",IF(F17>=Control!$B$20,"AMBER","RED")) -> GREEN | H17: 3 | I17: Re-cost products, review pricing and trim discretionary spend before reserves are touched.
A18: Reserve coverage (months of operating cost) | B18: =IFERROR($D$11/(($D$9+$D$10)/12),0) -> 5.6470588 | C18: 6 | D18: 2 | E18: Higher is better | F18: =IF(C18=D18,IF(B18>=C18,100,0),MAX(0,MIN(100,(B18-D18)/(C18-D18)*100))) -> 91.176471 | G18: =IF(F18>=Control!$B$19,"GREEN",IF(F18>=Control!$B$20,"AMBER","RED")) -> GREEN | H18: 3 | I18: Rebuild reserves to policy; freeze non-essential capital spend until coverage recovers.
A19: Income concentration (largest source / revenue) | B19: =IFERROR($D$12/$D$7,0) -> 0.22 | C19: 0.2 | D19: 0.4 | E19: Lower is better | F19: =IF(C19=D19,IF(B19>=C19,100,0),MAX(0,MIN(100,(B19-D19)/(C19-D19)*100))) -> 90 | G19: =IF(F19>=Control!$B$19,"GREEN",IF(F19>=Control!$B$20,"AMBER","RED")) -> GREEN | H19: 2 | I19: Diversify income; set a hard cap on any single source.
A20: Days sales outstanding | B20: =IFERROR($D$13,0) -> 52 | C20: 45 | D20: 75 | E20: Lower is better | F20: =IF(C20=D20,IF(B20>=C20,100,0),MAX(0,MIN(100,(B20-D20)/(C20-D20)*100))) -> 76.666667 | G20: =IF(F20>=Control!$B$19,"GREEN",IF(F20>=Control!$B$20,"AMBER","RED")) -> GREEN | H20: 1 | I20: Tighten credit terms and escalate overdue receivables weekly.
A21: Forecast accuracy | B21: =IFERROR(1-ABS($D$7-$D$8)/$D$8,0) -> 1 | C21: 0.97 | D21: 0.85 | E21: Higher is better | F21: =IF(C21=D21,IF(B21>=C21,100,0),MAX(0,MIN(100,(B21-D21)/(C21-D21)*100))) -> 100 | G21: =IF(F21>=Control!$B$19,"GREEN",IF(F21>=Control!$B$20,"AMBER","RED")) -> GREEN | H21: 1 | I21: Re-forecast quarterly and always present at least three scenarios.
A23: SECTOR SCORE (0-100, weighted) | B23: =SUMPRODUCT($F$17:$F$21,$H$17:$H$21)/SUM($H$17:$H$21) -> 93.019608
A24: SECTOR STATUS | B24: =IF(B23>=Control!$B$19,"GREEN",IF(B23>=Control!$B$20,"AMBER","RED")) -> GREEN
A25: WEAKEST KPI | B25: =INDEX($A$17:$A$21,MATCH(MIN($F$17:$F$21),$F$17:$F$21,0)) -> Days sales outstanding
A26: CHAIR'S PRIORITY ACTION | B26: =IF(MIN($F$17:$F$21)>=Control!$B$19,"Sector healthy. Keep the quarterly review and watch: "&B25,INDEX($I$17:$I$21,MATCH(MIN($F$17:$F$21),$F$17:$F$21,0))) -> Sector healthy. Keep the quarterly review and watch: Days sales outstanding

Sheet Audit
A1: 9. Audit
A2: Stance: audit must be independent enough to tell the Chair no. Findings are only worth something if they are closed.
A3: Active scenario: | B3: =Control!$B$4 -> Base Case
A5: A. INPUTS (blue on yellow = edit the base value; the scenario-adjusted column recalculates from the Control sheet)
A6: Input | B6: Unit | C6: Base value | D6: Scenario-adjusted | E6: Note
A7: Audit engagements planned | B7: count | C7: 40 | D7: =C7 -> 40
A8: Audit engagements completed | B8: count | C8: 36 | D8: =C8 -> 36
A9: Open findings | B9: count | C9: 28 | D9: =C9 -> 28
A10: Findings overdue against the agreed date | B10: count | C10: 6 | D10: =C10*Control!$G$16 -> 6
A11: Repeat findings | B11: count | C11: 3 | D11: =C11*Control!$G$16 -> 3
A12: Findings downgraded after management negotiation | B12: count | C12: 1 | D12: =C12*Control!$G$16 -> 1
A13: Years with the current external auditor | B13: years | C13: 3 | D13: =C13 -> 3 | E13: Rotation policy assumed at 5 years
A15: B. KPI DASHBOARD
A16: KPI | B16: Value | C16: Green at | D16: Red at | E16: Direction | F16: Score (0-100) | G16: Status | H16: Weight | I16: Chair's action if this is the weakest KPI
A17: Audit plan completion | B17: =IFERROR($D$8/$D$7,0) -> 0.9 | C17: 0.95 | D17: 0.75 | E17: Higher is better | F17: =IF(C17=D17,IF(B17>=C17,100,0),MAX(0,MIN(100,(B17-D17)/(C17-D17)*100))) -> 75 | G17: =IF(F17>=Control!$B$19,"GREEN",IF(F17>=Control!$B$20,"AMBER","RED")) -> GREEN | H17: 2 | I17: Protect audit capacity; re-plan on risk, not convenience.
A18: Overdue share of open findings | B18: =IFERROR(MIN(1,$D$10/$D$9),0) -> 0.21428571 | C18: 0.1 | D18: 0.4 | E18: Lower is better | F18: =IF(C18=D18,IF(B18>=C18,100,0),MAX(0,MIN(100,(B18-D18)/(C18-D18)*100))) -> 61.904762 | G18: =IF(F18>=Control!$B$19,"GREEN",IF(F18>=Control!$B$20,"AMBER","RED")) -> AMBER | H18: 3 | I18: Escalate every overdue finding to the Audit & Risk committee with the owner present.
A19: Repeat-finding share | B19: =IFERROR(MIN(1,$D$11/$D$9),0) -> 0.10714286 | C19: 0.05 | D19: 0.25 | E19: Lower is better | F19: =IF(C19=D19,IF(B19>=C19,100,0),MAX(0,MIN(100,(B19-D19)/(C19-D19)*100))) -> 71.428571 | G19: =IF(F19>=Control!$B$19,"GREEN",IF(F19>=Control!$B$20,"AMBER","RED")) -> GREEN | H19: 2 | I19: Fix root causes, not symptoms; track repeat findings on the board dashboard.
A20: Findings downgraded after negotiation | B20: =IFERROR($D$12,0) -> 1 | C20: 0 | D20: 4 | E20: Lower is better | F20: =IF(C20=D20,IF(B20>=C20,100,0),MAX(0,MIN(100,(B20-D20)/(C20-D20)*100))) -> 75 | G20: =IF(F20>=Control!$B$19,"GREEN",IF(F20>=Control!$B$20,"AMBER","RED")) -> GREEN | H20: 2 | I20: Require written justification and committee sign-off for any downgrade.
A21: External auditor tenure (years) | B21: =IFERROR($D$13,0) -> 3 | C21: 5 | D21: 9 | E21: Lower is better | F21: =IF(C21=D21,IF(B21>=C21,100,0),MAX(0,MIN(100,(B21-D21)/(C21-D21)*100))) -> 100 | G21: =IF(F21>=Control!$B$19,"GREEN",IF(F21>=Control!$B$20,"AMBER","RED")) -> GREEN | H21: 1 | I21: Run the auditor rotation process before the tenure limit is reached.
A23: SECTOR SCORE (0-100, weighted) | B23: =SUMPRODUCT($F$17:$F$21,$H$17:$H$21)/SUM($H$17:$H$21) -> 72.857143
A24: SECTOR STATUS | B24: =IF(B23>=Control!$B$19,"GREEN",IF(B23>=Control!$B$20,"AMBER","RED")) -> GREEN
A25: WEAKEST KPI | B25: =INDEX($A$17:$A$21,MATCH(MIN($F$17:$F$21),$F$17:$F$21,0)) -> Overdue share of open findings
A26: CHAIR'S PRIORITY ACTION | B26: =IF(MIN($F$17:$F$21)>=Control!$B$19,"Sector healthy. Keep the quarterly review and watch: "&B25,INDEX($I$17:$I$21,MATCH(MIN($F$17:$F$21),$F$17:$F$21,0))) -> Escalate every overdue finding to the Audit & Risk committee with the owner present.

Sheet Commercials
A1: 10. Commercials
A2: Stance: growth that breaks controls is borrowed from the future. Margin, concentration and clean terms come first.
A3: Active scenario: | B3: =Control!$B$4 -> Base Case
A5: A. INPUTS (blue on yellow = edit the base value; the scenario-adjusted column recalculates from the Control sheet)
A6: Input | B6: Unit | C6: Base value | D6: Scenario-adjusted | E6: Note
A7: Annual sales | B7: PKR m | C7: 12000 | D7: =C7*Control!$B$16 -> 12000 | E7: Illustrative figures; replace with your own
A8: Cost of goods sold | B8: PKR m | C8: 9120 | D8: =C8*Control!$C$16 -> 9120
A9: Sales to the largest customer | B9: PKR m | C9: 1920 | D9: =C9 -> 1920
A10: Active contracts | B10: count | C10: 150 | D10: =C10 -> 150
A11: Contracts approved outside standard terms | B11: count | C11: 6 | D11: =C11*Control!$J$16 -> 6
A12: Receivables older than 90 days | B12: PKR m | C12: 600 | D12: =C12*(1+Control!$E$16/30) -> 600
A13: Contracts due for renewal | B13: count | C13: 100 | D13: =C13 -> 100
A14: Contracts renewed | B14: count | C14: 82 | D14: =C14*Control!$B$16 -> 82
A16: B. KPI DASHBOARD
A17: KPI | B17: Value | C17: Green at | D17: Red at | E17: Direction | F17: Score (0-100) | G17: Status | H17: Weight | I17: Chair's action if this is the weakest KPI
A18: Gross margin | B18: =IFERROR(($D$7-$D$8)/$D$7,0) -> 0.24 | C18: 0.25 | D18: 0.1 | E18: Higher is better | F18: =IF(C18=D18,IF(B18>=C18,100,0),MAX(0,MIN(100,(B18-D18)/(C18-D18)*100))) -> 93.333333 | G18: =IF(F18>=Control!$B$19,"GREEN",IF(F18>=Control!$B$20,"AMBER","RED")) -> GREEN | H18: 3 | I18: Reprice or renegotiate; stop volume deals that dilute margin.
A19: Largest-customer concentration | B19: =IFERROR($D$9/$D$7,0) -> 0.16 | C19: 0.15 | D19: 0.3 | E19: Lower is better | F19: =IF(C19=D19,IF(B19>=C19,100,0),MAX(0,MIN(100,(B19-D19)/(C19-D19)*100))) -> 93.333333 | G19: =IF(F19>=Control!$B$19,"GREEN",IF(F19>=Control!$B$20,"AMBER","RED")) -> GREEN | H19: 2 | I19: Set an exposure cap and a diversification target for the next 12 months.
A20: Contracts outside standard terms | B20: =IFERROR($D$11/$D$10,0) -> 0.04 | C20: 0.02 | D20: 0.1 | E20: Lower is better | F20: =IF(C20=D20,IF(B20>=C20,100,0),MAX(0,MIN(100,(B20-D20)/(C20-D20)*100))) -> 75 | G20: =IF(F20>=Control!$B$19,"GREEN",IF(F20>=Control!$B$20,"AMBER","RED")) -> GREEN | H20: 2 | I20: Require written approval for any deviation; escalate verbal commitments.
A21: Receivables > 90 days (share of sales) | B21: =IFERROR($D$12/$D$7,0) -> 0.05 | C21: 0.03 | D21: 0.1 | E21: Lower is better | F21: =IF(C21=D21,IF(B21>=C21,100,0),MAX(0,MIN(100,(B21-D21)/(C21-D21)*100))) -> 71.428571 | G21: =IF(F21>=Control!$B$19,"GREEN",IF(F21>=Control!$B$20,"AMBER","RED")) -> GREEN | H21: 2 | I21: Escalate the oldest balances; pause new orders for chronic late payers.
A22: Contract renewal rate | B22: =IFERROR($D$14/$D$13,0) -> 0.82 | C22: 0.9 | D22: 0.65 | E22: Higher is better | F22: =IF(C22=D22,IF(B22>=C22,100,0),MAX(0,MIN(100,(B22-D22)/(C22-D22)*100))) -> 68 | G22: =IF(F22>=Control!$B$19,"GREEN",IF(F22>=Control!$B$20,"AMBER","RED")) -> AMBER | H22: 1 | I22: Start renewal conversations 120 days out; review churn reasons.
A24: SECTOR SCORE (0-100, weighted) | B24: =SUMPRODUCT($F$18:$F$22,$H$18:$H$22)/SUM($H$18:$H$22) -> 82.752381
A25: SECTOR STATUS | B25: =IF(B24>=Control!$B$19,"GREEN",IF(B24>=Control!$B$20,"AMBER","RED")) -> GREEN
A26: WEAKEST KPI | B26: =INDEX($A$18:$A$22,MATCH(MIN($F$18:$F$22),$F$18:$F$22,0)) -> Contract renewal rate
A27: CHAIR'S PRIORITY ACTION | B27: =IF(MIN($F$18:$F$22)>=Control!$B$19,"Sector healthy. Keep the quarterly review and watch: "&B26,INDEX($I$18:$I$22,MATCH(MIN($F$18:$F$22),$F$18:$F$22,0))) -> Start renewal conversations 120 days out; review churn reasons.

Sheet Procurement
A1: 11. Procurement
A2: Stance: procurement protects both cost and continuity, and supply shocks are now a board-level risk.
A3: Active scenario: | B3: =Control!$B$4 -> Base Case
A5: A. INPUTS (blue on yellow = edit the base value; the scenario-adjusted column recalculates from the Control sheet)
A6: Input | B6: Unit | C6: Base value | D6: Scenario-adjusted | E6: Note
A7: Total annual spend | B7: PKR m | C7: 7000 | D7: =C7*Control!$C$16 -> 7000 | E7: Illustrative figures; replace with your own
A8: Spend with single-source suppliers | B8: PKR m | C8: 1260 | D8: =C8*Control!$C$16 -> 1260
A9: Critical categories | B9: count | C9: 14 | D9: =C9 -> 14
A10: Critical categories with a documented plan B | B10: count | C10: 10 | D10: =C10 -> 10
A11: Supplier on-time delivery | B11: % | C11: 0.92 | D11: =C11*Control!$D$16 -> 0.92
A12: Purchase orders raised | B12: count | C12: 600 | D12: =C12 -> 600
A13: Emergency purchase orders | B13: count | C13: 18 | D13: =C13*(1+(1-Control!$D$16)*10) -> 18
A14: Savings claimed | B14: PKR m | C14: 210 | D14: =C14 -> 210
A15: Savings verified by Finance | B15: PKR m | C15: 168 | D15: =C15 -> 168
A16: Commodity-linked spend | B16: PKR m | C16: 2800 | D16: =C16*Control!$C$16 -> 2800
A17: Of which hedged, fixed-price or buffered | B17: PKR m | C17: 1260 | D17: =C17 -> 1260
A19: B. KPI DASHBOARD
A20: KPI | B20: Value | C20: Green at | D20: Red at | E20: Direction | F20: Score (0-100) | G20: Status | H20: Weight | I20: Chair's action if this is the weakest KPI
A21: Single-source spend share | B21: =IFERROR($D$8/$D$7,0) -> 0.18 | C21: 0.1 | D21: 0.3 | E21: Lower is better | F21: =IF(C21=D21,IF(B21>=C21,100,0),MAX(0,MIN(100,(B21-D21)/(C21-D21)*100))) -> 60 | G21: =IF(F21>=Control!$B$19,"GREEN",IF(F21>=Control!$B$20,"AMBER","RED")) -> AMBER | H21: 2 | I21: Qualify alternate suppliers for the largest single-source categories first.
A22: Plan-B coverage of critical categories | B22: =IFERROR($D$10/$D$9,0) -> 0.71428571 | C22: 0.9 | D22: 0.5 | E22: Higher is better | F22: =IF(C22=D22,IF(B22>=C22,100,0),MAX(0,MIN(100,(B22-D22)/(C22-D22)*100))) -> 53.571429 | G22: =IF(F22>=Control!$B$19,"GREEN",IF(F22>=Control!$B$20,"AMBER","RED")) -> AMBER | H22: 2 | I22: Write and test a plan B for every critical category without one.
A23: Supplier on-time delivery | B23: =IFERROR($D$11,0) -> 0.92 | C23: 0.95 | D23: 0.8 | E23: Higher is better | F23: =IF(C23=D23,IF(B23>=C23,100,0),MAX(0,MIN(100,(B23-D23)/(C23-D23)*100))) -> 80 | G23: =IF(F23>=Control!$B$19,"GREEN",IF(F23>=Control!$B$20,"AMBER","RED")) -> GREEN | H23: 3 | I23: Put chronic late suppliers on a performance plan; buffer stock for critical items.
A24: Emergency purchase share | B24: =IFERROR($D$13/$D$12,0) -> 0.03 | C24: 0.02 | D24: 0.1 | E24: Lower is better | F24: =IF(C24=D24,IF(B24>=C24,100,0),MAX(0,MIN(100,(B24-D24)/(C24-D24)*100))) -> 87.5 | G24: =IF(F24>=Control!$B$19,"GREEN",IF(F24>=Control!$B$20,"AMBER","RED")) -> GREEN | H24: 2 | I24: Treat every emergency PO as an incident; fix the planning gap behind it.
A25: Savings verified by Finance | B25: =IFERROR($D$15/$D$14,0) -> 0.8 | C25: 0.9 | D25: 0.6 | E25: Higher is better | F25: =IF(C25=D25,IF(B25>=C25,100,0),MAX(0,MIN(100,(B25-D25)/(C25-D25)*100))) -> 66.666667 | G25: =IF(F25>=Control!$B$19,"GREEN",IF(F25>=Control!$B$20,"AMBER","RED")) -> AMBER | H25: 1 | I25: Count only savings Finance has verified against the baseline.
A26: Unhedged commodity-linked spend (share of total) | B26: =IFERROR(MAX(0,$D$16-$D$17)/$D$7,0) -> 0.22 | C26: 0.2 | D26: 0.5 | E26: Lower is better | F26: =IF(C26=D26,IF(B26>=C26,100,0),MAX(0,MIN(100,(B26-D26)/(C26-D26)*100))) -> 93.333333 | G26: =IF(F26>=Control!$B$19,"GREEN",IF(F26>=Control!$B$20,"AMBER","RED")) -> GREEN | H26: 2 | I26: Extend fixed-price, buffer or hedge cover on the largest exposed commodities.
A28: SECTOR SCORE (0-100, weighted) | B28: =SUMPRODUCT($F$21:$F$26,$H$21:$H$26)/SUM($H$21:$H$26) -> 74.623016
A29: SECTOR STATUS | B29: =IF(B28>=Control!$B$19,"GREEN",IF(B28>=Control!$B$20,"AMBER","RED")) -> GREEN
A30: WEAKEST KPI | B30: =INDEX($A$21:$A$26,MATCH(MIN($F$21:$F$26),$F$21:$F$26,0)) -> Plan-B coverage of critical categories
A31: CHAIR'S PRIORITY ACTION | B31: =IF(MIN($F$21:$F$26)>=Control!$B$19,"Sector healthy. Keep the quarterly review and watch: "&B30,INDEX($I$21:$I$26,MATCH(MIN($F$21:$F$26),$F$21:$F$26,0))) -> Write and test a plan B for every critical category without one.

Sheet Production
A1: 12. Production
A2: Stance: production is where strategy becomes product, and where resilience is physical. Safety and quality are board metrics, not afterthoughts.
A3: Active scenario: | B3: =Control!$B$4 -> Base Case
A5: A. INPUTS (blue on yellow = edit the base value; the scenario-adjusted column recalculates from the Control sheet)
A6: Input | B6: Unit | C6: Base value | D6: Scenario-adjusted | E6: Note
A7: Planned output | B7: units | C7: 1000 | D7: =C7 -> 1000 | E7: In thousands of units
A8: Actual output | B8: units | C8: 960 | D8: =C8*Control!$D$16 -> 960
A9: Planned production hours | B9: hours | C9: 6000 | D9: =C9 -> 6000
A10: Unplanned downtime | B10: hours | C10: 240 | D10: =C10*Control!$I$16 -> 240
A11: Defective units | B11: units | C11: 18 | D11: =C11*Control!$I$16 -> 18
A12: Lost-time injuries | B12: count | C12: 2 | D12: =C12*Control!$I$16 -> 2
A13: Critical spares availability | B13: % | C13: 0.92 | D13: =C13*Control!$D$16 -> 0.92
A15: B. KPI DASHBOARD
A16: KPI | B16: Value | C16: Green at | D16: Red at | E16: Direction | F16: Score (0-100) | G16: Status | H16: Weight | I16: Chair's action if this is the weakest KPI
A17: Schedule adherence | B17: =IFERROR($D$8/$D$7,0) -> 0.96 | C17: 0.97 | D17: 0.8 | E17: Higher is better | F17: =IF(C17=D17,IF(B17>=C17,100,0),MAX(0,MIN(100,(B17-D17)/(C17-D17)*100))) -> 94.117647 | G17: =IF(F17>=Control!$B$19,"GREEN",IF(F17>=Control!$B$20,"AMBER","RED")) -> GREEN | H17: 3 | I17: Run a daily constraint meeting; link the plan to procurement and finance monthly.
A18: Unplanned downtime share | B18: =IFERROR($D$10/$D$9,0) -> 0.04 | C18: 0.03 | D18: 0.1 | E18: Lower is better | F18: =IF(C18=D18,IF(B18>=C18,100,0),MAX(0,MIN(100,(B18-D18)/(C18-D18)*100))) -> 85.714286 | G18: =IF(F18>=Control!$B$19,"GREEN",IF(F18>=Control!$B$20,"AMBER","RED")) -> GREEN | H18: 2 | I18: Move from reactive to planned maintenance; review the top five failure causes.
A19: Defect rate | B19: =IFERROR($D$11/$D$8,0) -> 0.01875 | C19: 0.015 | D19: 0.06 | E19: Lower is better | F19: =IF(C19=D19,IF(B19>=C19,100,0),MAX(0,MIN(100,(B19-D19)/(C19-D19)*100))) -> 91.666667 | G19: =IF(F19>=Control!$B$19,"GREEN",IF(F19>=Control!$B$20,"AMBER","RED")) -> GREEN | H19: 2 | I19: Stop-and-fix at source; track defects by cause and by shift.
A20: Lost-time injuries | B20: =IFERROR($D$12,0) -> 2 | C20: 0 | D20: 5 | E20: Lower is better | F20: =IF(C20=D20,IF(B20>=C20,100,0),MAX(0,MIN(100,(B20-D20)/(C20-D20)*100))) -> 60 | G20: =IF(F20>=Control!$B$19,"GREEN",IF(F20>=Control!$B$20,"AMBER","RED")) -> AMBER | H20: 3 | I20: Treat every injury as a board-level event; independent safety review within 30 days.
A21: Critical spares availability | B21: =IFERROR($D$13,0) -> 0.92 | C21: 0.95 | D21: 0.75 | E21: Higher is better | F21: =IF(C21=D21,IF(B21>=C21,100,0),MAX(0,MIN(100,(B21-D21)/(C21-D21)*100))) -> 85 | G21: =IF(F21>=Control!$B$19,"GREEN",IF(F21>=Control!$B$20,"AMBER","RED")) -> GREEN | H21: 1 | I21: Stock the critical-spares list and secure alternate suppliers for long-lead items.
A23: SECTOR SCORE (0-100, weighted) | B23: =SUMPRODUCT($F$17:$F$21,$H$17:$H$21)/SUM($H$17:$H$21) -> 82.010441
A24: SECTOR STATUS | B24: =IF(B23>=Control!$B$19,"GREEN",IF(B23>=Control!$B$20,"AMBER","RED")) -> GREEN
A25: WEAKEST KPI | B25: =INDEX($A$17:$A$21,MATCH(MIN($F$17:$F$21),$F$17:$F$21,0)) -> Lost-time injuries
A26: CHAIR'S PRIORITY ACTION | B26: =IF(MIN($F$17:$F$21)>=Control!$B$19,"Sector healthy. Keep the quarterly review and watch: "&B25,INDEX($I$17:$I$21,MATCH(MIN($F$17:$F$21),$F$17:$F$21,0))) -> Treat every injury as a board-level event; independent safety review within 30 days.

Sheet Mock_Test
A1: Mock Test: Chair's Judgement Under Pressure
A2: Part A: 24 questions (two per sector), auto-scored. Part B: predict which sector breaks first under each scenario, then check it against the live Dashboard.
B3: Reveal answers and explanations? | C3: No
B5: Questions answered | C5: =COUNTA(H12:H35) -> 0
B6: Correct | C6: =COUNTIF(I12:I35,"Correct") -> 0
B7: Part A score | C7: =C6/24 -> 0
B8: Result | C8: =IF(C5<24,"Answer all 24 questions to get a result",IF(C7>=0.85,"Chair-ready",IF(C7>=0.7,"Board-ready",IF(C7>=0.5,"Developing: revisit the sector tabs","Revisit the roadmap and try again")))) -> Answer all 24 questions to get a result
A11: # | B11: Sector | C11: Question | D11: A | E11: B | F11: C | G11: D | H11: Your answer | I11: Result | J11: Correct answer | K11: Why (shown when Reveal = Yes) | L11: Key | M11: Expl
A12: 1 | B12: Government Affairs | C12: A key regulator relationship depends entirely on one senior person. What is the Chair's best first move? | D12: Leave it alone; relationships are personal by nature. | E12: Document the channel and assign a second named institutional contact. | F12: Replace the person immediately. | G12: Ask the regulator to deal only with the Chair. | I12: =IF(H12="","",IF(H12=L12,"Correct","Incorrect")) | J12: =IF($C$3="Yes",L12,"(hidden)") -> (hidden) | K12: =IF($C$3="Yes",M12,"(hidden until Reveal = Yes)") -> (hidden until Reveal = Yes) | L12: B | M12: Relationships belong to the institution. Document the channel and build contact depth before the dependency becomes a risk.
A13: 2 | B13: Government Affairs | C13: Who should own the regulatory compliance calendar? | D13: Audit / compliance, independent of the lobbying function | E13: The lobbying function, since it knows the regulators best | F13: The Chair's office | G13: An external consultant with no internal owner | I13: =IF(H13="","",IF(H13=L13,"Correct","Incorrect")) | J13: =IF($C$3="Yes",L13,"(hidden)") -> (hidden) | K13: =IF($C$3="Yes",M13,"(hidden until Reveal = Yes)") -> (hidden until Reveal = Yes) | L13: A | M13: Compliance deadlines are control obligations. Ownership sits with Audit or compliance, not with the function that lobbies.
A14: 3 | B14: Policy Making | C14: Frequent exceptions to a policy usually indicate: | D14: Staff are being efficient | E14: Strong governance | F14: The policy is wrong or is being ignored | G14: Nothing worth tracking | I14: =IF(H14="","",IF(H14=L14,"Correct","Incorrect")) | J14: =IF($C$3="Yes",L14,"(hidden)") -> (hidden) | K14: =IF($C$3="Yes",M14,"(hidden until Reveal = Yes)") -> (hidden until Reveal = Yes) | L14: C | M14: A high exception rate means the policy no longer fits reality or is not enforced. Rewrite it or enforce it.
A15: 4 | B15: Policy Making | C15: Which set of fields belongs in every policy-register entry? | D15: Title and author only | E15: Approval date only | F15: A list of staff who have read it | G15: Purpose, scope, owner, exceptions path and review date | I15: =IF(H15="","",IF(H15=L15,"Correct","Incorrect")) | J15: =IF($C$3="Yes",L15,"(hidden)") -> (hidden) | K15: =IF($C$3="Yes",M15,"(hidden until Reveal = Yes)") -> (hidden until Reveal = Yes) | L15: D | M15: A policy without an owner and review date drifts out of date. Purpose, scope and exceptions make it usable.
A16: 5 | B16: Public Affairs | C16: Stakeholders keep hearing major institutional news from outside sources first. This most likely signals: | D16: Normal media behaviour | E16: A failed crisis-communication protocol or spokesperson list | F16: Excellent transparency | G16: Biased journalists | I16: =IF(H16="","",IF(H16=L16,"Correct","Incorrect")) | J16: =IF($C$3="Yes",L16,"(hidden)") -> (hidden) | K16: =IF($C$3="Yes",M16,"(hidden until Reveal = Yes)") -> (hidden until Reveal = Yes) | L16: B | M16: The institution should be the first and clearest voice on its own news. Fix the protocol and the authorized spokesperson list.
A17: 6 | B17: Public Affairs | C17: Holding statements should be: | D17: Written after the crisis peaks | E17: Replaced by the annual report | F17: Prepared in advance for the likely shocks and pre-approved | G17: Issued only by lawyers | I17: =IF(H17="","",IF(H17=L17,"Correct","Incorrect")) | J17: =IF($C$3="Yes",L17,"(hidden)") -> (hidden) | K17: =IF($C$3="Yes",M17,"(hidden until Reveal = Yes)") -> (hidden until Reveal = Yes) | L17: C | M17: Speed matters in the first hours. Pre-approved statements for likely scenarios let you respond before rumours set.
A18: 7 | B18: Public Interest | C18: A member's interest conflicts with the wider public interest. The Chair should: | D18: Disclose the conflict and decide openly with the reasoning recorded | E18: Always favour the member | F18: Resolve it privately and report nothing | G18: Defer to government automatically | I18: =IF(H18="","",IF(H18=L18,"Correct","Incorrect")) | J18: =IF($C$3="Yes",L18,"(hidden)") -> (hidden) | K18: =IF($C$3="Yes",M18,"(hidden until Reveal = Yes)") -> (hidden until Reveal = Yes) | L18: A | M18: Legitimacy comes from open, reasoned decisions. Disclosure protects the institution even when the outcome is unpopular.
A19: 8 | B19: Public Interest | C19: Whistleblower channels should reach: | D19: Only the line manager involved | E19: The Chair's personal assistant | F19: The department being complained about | G19: The Audit & Risk committee directly | I19: =IF(H19="","",IF(H19=L19,"Correct","Incorrect")) | J19: =IF($C$3="Yes",L19,"(hidden)") -> (hidden) | K19: =IF($C$3="Yes",M19,"(hidden until Reveal = Yes)") -> (hidden until Reveal = Yes) | L19: D | M19: A channel that passes through the people complained about will not be used. Route reports to an independent committee.
A20: 9 | B20: Human Resources | C20: The best single measure of succession depth is: | D20: Number of CVs received | E20: Total training hours | F20: Share of critical roles with a ready-now successor | G20: Headcount growth | I20: =IF(H20="","",IF(H20=L20,"Correct","Incorrect")) | J20: =IF($C$3="Yes",L20,"(hidden)") -> (hidden) | K20: =IF($C$3="Yes",M20,"(hidden until Reveal = Yes)") -> (hidden until Reveal = Yes) | L20: C | M20: Succession depth is about readiness for critical roles, not activity or volume.
